<robot name="robot_pit">

    <!-- Base link -->
    <link name="base_link">
        <!-- No se necesitan propiedades visuales o de colisión para base_link -->
    </link>

    <!-- Chassis link -->
    <link name="chassis_link">
        <visual>
            <origin xyz="0.0 0.0 0.0" rpy="0.0 0.0 0.0"/>
            <geometry>
                <box size="0.8 0.5 0.2"/>
            </geometry>
            <material name="rojo">
                <color rgba="1.0 0.0 0.0 1.0"/>
            </material>
        </visual>

        <!-- Colisión del chasis -->
        <collision>
            <origin xyz="0.0 0.0 0.0" rpy="0.0 0.0 0.0"/>
            <geometry>
                <box size="0.8 0.5 0.2"/>
            </geometry>
        </collision>

        <!-- Inercia del chasis -->
        <inertial>
            <mass value="5.0"/>  <!-- Masa del chasis en kg -->
            <origin xyz="0.0 0.0 0.0"/>
            <inertia ixx="0.1" ixy="0.0" ixz="0.0" iyy="0.1" iyz="0.0" izz="0.1"/>
        </inertial>
    </link>

    <!-- Joint entre base_link y chassis_link -->
    <joint name="joint_base_chassis" type="fixed">
        <origin xyz="0.0 0.0 0.2" rpy="0.0 0.0 0.0"/>
        <parent link="base_link"/>
        <child link="chassis_link"/>
    </joint>

    <!-- Rueda derecha -->
    <link name="rueda_derecha_link">
        <visual>
            <origin xyz="0.0 0.0 0.0" rpy="0.0 0.0 0.0"/>  <!-- Rotada 90 grados en X -->
            <geometry>
                <cylinder radius="0.20" length="0.05"/>
            </geometry>
            <material name="azul">
                <color rgba="0.0 0.0 1.0 1.0"/>
            </material>
        </visual>

        <!-- Colisión de la rueda derecha -->
        <collision>
            <origin xyz="0.0 0.0 0.0" rpy="0.0 0.0 0.0"/>
            <geometry>
                <cylinder radius="0.20" length="0.05"/>
            </geometry>
        </collision>

        <!-- Inercia de la rueda derecha -->
        <inertial>
            <mass value="1.0"/>  <!-- Masa de la rueda en kg -->
            <origin xyz="0.0 0.0 0.0"/>
            <inertia ixx="0.01" ixy="0.0" ixz="0.0" iyy="0.01" iyz="0.0" izz="0.02"/>
        </inertial>
    </link>

    <!-- Joint entre chassis_link y rueda derecha -->
    <joint name="joint_chassis_rueda_derecha" type="continuous">
        <origin xyz="0.0 -0.275 0.0" rpy="1.57 0.0 0.0"/>
        <parent link="chassis_link"/>
        <child link="rueda_derecha_link"/>
        <axis xyz="0.0 0.0 -1.0"/>
    </joint>

    <!-- Rueda izquierda -->
    <link name="rueda_izquierda_link">
        <visual>
            <origin xyz="0.0 0.0 0.0" rpy="0.0 0.0 0.0"/>  <!-- Rotada 90 grados en X -->
            <geometry>
                <cylinder radius="0.20" length="0.05"/>
            </geometry>
            <material name="azul">
                <color rgba="0.0 0.0 1.0 1.0"/>
            </material>
        </visual>

        <!-- Colisión de la rueda izquierda -->
        <collision>
            <origin xyz="0.0 0.0 0.0" rpy="0.0 0.0 0.0"/>
            <geometry>
                <cylinder radius="0.20" length="0.05"/>
            </geometry>
        </collision>

        <!-- Inercia de la rueda izquierda -->
        <inertial>
            <mass value="1.0"/>  <!-- Masa de la rueda en kg -->
            <origin xyz="0.0 0.0 0.0"/>
            <inertia ixx="0.01" ixy="0.0" ixz="0.0" iyy="0.01" iyz="0.0" izz="0.02"/>
        </inertial>
    </link>

    <!-- Joint entre chassis_link y rueda izquierda -->
    <joint name="joint_chassis_rueda_izquierda" type="continuous">
        <origin xyz="0.0 0.275 0.0" rpy="1.57 0.0 0.0"/>
        <parent link="chassis_link"/>
        <child link="rueda_izquierda_link"/>
        <axis xyz="0.0 0.0 -1.0"/>
    </joint>

    <!-- Rueda caster (rueda de soporte) -->
    <link name="rueda_caster_link">
        <visual>
            <origin xyz="0.0 0.0 0.0" rpy="0.0 0.0 0.0"/>
            <geometry>
                <sphere radius="0.10"/>
            </geometry>
            <material name="anaranjado">
                <color rgba="0.5 0.5 0.0 1.0"/>
            </material>
        </visual>

        <!-- Colisión de la rueda caster -->
        <collision>
            <origin xyz="0.0 0.0 0.0" rpy="0.0 0.0 0.0"/>
            <geometry>
                <sphere radius="0.10"/>
            </geometry>
        </collision>

        <!-- Inercia de la rueda caster -->
        <inertial>
            <mass value="0.1"/>  <!-- Masa de la rueda caster en kg -->
            <origin xyz="0.0 0.0 0.0"/>
            <inertia ixx="0.001" ixy="0.0" ixz="0.0" iyy="0.001" iyz="0.0" izz="0.001"/>
        </inertial>
    </link>

    <!-- Joint entre chassis_link y rueda caster -->
    <joint name="joint_chassis_rueda_caster" type="fixed">
        <origin xyz="0.3 0.0 -0.1" rpy="0.0 0.0 0.0"/>
        <parent link="chassis_link"/>
        <child link="rueda_caster_link"/>
    </joint>

    <link name="rueda_caster_falso_link">
        <!--visual>
            <origin xyz="0.0 0.0 0.0" rpy="0.0 0.0 0.0"/>
            <geometry>
                <sphere radius="0.10"/>
            </geometry>
            <material name="anaranjado">
                <color rgba="0.5 0.5 0.0 1.0"/>
            </material>
        </visual-->

        <collision>
            <origin xyz="0.0 0.0 0.0" rpy="0.0 0.0 0.0"/>
            <geometry>
                <sphere radius="0.10"/>
            </geometry>
        </collision>

        <inertial>
            <mass value="0.1"/>  
            <origin xyz="0.0 0.0 0.0"/>
            <inertia ixx="0.001" ixy="0.0" ixz="0.0" iyy="0.001" iyz="0.0" izz="0.001"/>
        </inertial>
    </link>

    <joint name="joint_chassis_rueda_caster_falso" type="fixed">
        <origin xyz="-0.3 0.0 -0.1" rpy="0.0 0.0 0.0"/>
        <parent link="chassis_link"/>
        <child link="rueda_caster_falso_link"/>
    </joint>

    <!-- Laser sensor-->

    <link name="laser_link">
        <visual>
            <origin xyz="0.0 0.0 0.0" rpy="0.0 0.0 0.0"/>
            <geometry>
                <box size="0.1 0.1 0.1"/>
            </geometry>
            <material name="anaranjado">
                <color rgba="0.5 0.5 0.0 1.0"/>
            </material>
        </visual>

        <collision>
            <origin xyz="0.0 0.0 0.0" rpy="0.0 0.0 0.0"/>
            <geometry>
                <box size="0.1 0.1 0.1"/>
            </geometry>
        </collision>

        <inertial>
            <mass value="0.1"/>  
            <origin xyz="0.0 0.0 0.0"/>
            <inertia ixx="0.001" ixy="0.0" ixz="0.0" iyy="0.001" iyz="0.0" izz="0.001"/>
        </inertial>
    </link>

    <joint name="joint_chassis_laser" type="fixed">
        <origin xyz="0.0 0.0 0.15" rpy="0.0 0.0 0.0"/>
        <parent link="chassis_link"/>
        <child link="laser_link"/>
    </joint>


    <gazebo reference="rueda_izquierda_link">
        <kp>100000.0</kp>
        <kd>100000.0</kd>
        <mu1>10.0</mu1>
        <mu2>10.0</mu2>
        <material>Gazebo/Blue</material>
    </gazebo>
    <gazebo reference="rueda_derecha_link">
        <kp>100000.0</kp>
        <kd>100000.0</kd>
        <mu1>10.0</mu1>
        <mu2>10.0</mu2>
        <material>Gazebo/Blue</material>
    </gazebo>
    <gazebo reference="rueda_caster_link">
        <kp>100000.0</kp>
        <kd>100000.0</kd>
        <mu1>0.0</mu1>
        <mu2>0.0</mu2>
        <material>Gazebo/Red</material>
    </gazebo>

    <gazebo reference="rueda_caster_falso_link">
        <kp>100000.0</kp>
        <kd>1000000.0</kd>
        <mu1>0.0</mu1>
        <mu2>0.0</mu2>
        <material>Gazebo/Red</material>
    </gazebo>

    <gazebo>
        <plugin filename="libgazebo_ros_diff_drive.so" name="differential_drive_controller">
            <alwaysOn>true</alwaysOn>

            <updateRate>20</updateRate>

            <leftJoint>joint_chassis_rueda_izquierda</leftJoint>

            <rightJoint>joint_chassis_rueda_derecha</rightJoint>

            <wheelSeparation>0.55</wheelSeparation>

            <wheelDiameter>0.4</wheelDiameter>
            <torque>10</torque>

            <commandTopic>cmd_vel</commandTopic>

            <odometryTopic>odom</odometryTopic>

            <odometryFrame>odom</odometryFrame>

            <robotBaseFrame>base_link</robotBaseFrame>

            <publishWheelJointState>true</publishWheelJointState>

        </plugin>
    </gazebo>


    <gazebo reference="laser_link">
        <sensor type="ray" name="laser_sensor">
            <pose>0 0 0 0 0 0</pose>
            <visualize>true</visualize>
            <update_rate>20</update_rate>
            <ray>
                <scan>
                    <horizontal>
                    <samples>720</samples>
                        <resolution>1</resolution>
                        <min_angle>-1.570796</min_angle>
                        <max_angle>1.570796</max_angle>
                    </horizontal>
                </scan>
                <range>
                    <min>0.20</min>
                    <max>10.0</max>
                    <resolution>0.01</resolution>
                </range>
                <noise>
                    <type>gaussian</type>
                    <mean>0.0</mean>
                    <stddev>0.01</stddev>
                </noise>
            </ray>
            <plugin name="gazebo_ros_head_hokuyo_controller" filename="libgazebo_ros_laser.so">
                <topicName>/laser/scan</topicName>
                <frameName>laser_link</frameName>
            </plugin>
        </sensor>
    </gazebo>
</robot>